<?xml version="1.0"?>
<robot name="gripper">
  <link name="gripper_base_link">
    <inertial>
      <mass value="1"/>
      <inertia ixx="1" iyy="1" izz="1" ixy="0" ixz="0" iyz="0"/>
    </inertial>
  </link>
  <link name="gripper_ee_link">
    <inertial>
      <mass value="1"/>
      <inertia ixx="1" iyy="1" izz="1" ixy="0" ixz="0" iyz="0"/>
    </inertial>
  </link>
  <joint name="gripper_joint" type="revolute">
    <parent link="gripper_base_link"/>
    <child link="gripper_ee_link"/>
  </joint>
  <transmission name="gripper_joint_trans">
    <type>transmission_interface/SimpleTransmission</type>
    <joint name="gripper_joint">
      <hardwareInterface>hardware_interface/PositionJointInterface</hardwareInterface>
    </joint>
    <actuator name="gripper_joint_actuator">
      <mechanicalReduction>14</mechanicalReduction>
    </actuator>
  </transmission>
</robot>
